<?xml version="1.0"?>
<robot xmlns:xacro="http://www.ros.org/wiki/xacro" name="fellahbot">

  <xacro:include filename="$(find fellahbot_description)/urdf/constants.xacro"/>
  <xacro:include filename="$(find fellahbot_description)/urdf/inertials.xacro"/>
  <xacro:include filename="$(find fellahbot_description)/urdf/materials.xacro"/>
  <xacro:include filename="$(find fellahbot_description)/urdf/plugin.gazebo.xacro"/>
  <xacro:include filename="$(find fellahbot_description)/urdf/wheel.xacro"/>



  <link name="base_link"/>

  <joint name="base_robot" type="fixed">
    <parent link="base_link"/>
    <child link="chassis"/>
    <origin rpy="0 0 0" xyz="0 0 0.359"/>
  </joint>


  <link name="chassis">
    <visual>
      <geometry>
        <mesh filename="package://fellahbot_description/meshes/Fellahbot_DAE/Parts/ChassisRobot-Fusion001.dae"/>
      </geometry>
      <origin rpy="0 0 0" xyz="0 0 0"/>
      <material name="silver"/>
    </visual>
    <collision>
      <geometry>
        <box size="${chassis_length} ${chassis_width} ${chassis_height}"/>
      </geometry>
    </collision>
    <xacro:default_inertial mass="50"/>
  </link>


  <link name="lidar">
    <visual>
      <geometry>
        <mesh filename="package://fellahbot_description/meshes/Fellahbot_DAE/Parts/Support_lidar-Body.dae"/>
      </geometry>
      <material name="black"/>
    </visual>
    <collision>
      <geometry>
        <mesh filename="package://fellahbot_description/meshes/Fellahbot_DAE/Parts/Support_lidar-Body.dae"/>
      </geometry>
    </collision>
    <xacro:solid_cylinder_inertial rpy="0 0 0" xyz="0.455 0.0 -0.028" mass="0.3" radius="0.04" length="0.06" />
  </link>

  <joint name="base_lidar" type="fixed">
    <parent link="chassis"/>
    <child link="lidar"/>
    <origin xyz="0.455 0.0 -0.028"/>
  </joint>



  <link name="camera">
    <visual>
      <geometry>
        <box size="0.01 .06 0.03"/>
      </geometry>
      <origin rpy="0 0 0" xyz="0 0 0"/>
      <material name="black"/>
    </visual>
    <collision>
      <geometry>
        <box size="0.01 .06 0.03"/>
      </geometry>
    </collision>
     <xacro:solid_cuboid_inertial rpy="0 0 0" xyz="0.555 0.0 0.130" mass="0.2" x="0.01" y="0.06" z="0.03" />
    <xacro:default_inertial mass="0.2"/>
  </link>

  <joint name="base_camera" type="fixed">
    <parent link="chassis"/>
    <child link="camera"/>
    <origin xyz="0.555 0.0 0.130"/>
  </joint>



  <link name="phare">
    <visual>
      <geometry>
        <cylinder radius="0.025" length="0.290"/>
      </geometry>
      <origin rpy="${math_pi_over_2} 0 0" xyz="0 0 0"/>
      <material name="white"/>
    </visual>
    <collision>
      <geometry>
        <cylinder radius="0.03" length="0.3"/>
      </geometry>
      <origin rpy="${math_pi_over_2} 0 0" xyz="0 0 0"/>
    </collision>
    <xacro:solid_cylinder_inertial rpy="0 0 0" xyz="0.556 0.0 0.27444" mass="0.5" radius="0.025" length="0.29" />
  </link>

  <joint name="base_phare" type="fixed">
    <parent link="chassis"/>
    <child link="phare"/>
    <origin xyz="0.556 0.0 0.27444"/>
  </joint>



  <link name="castor_1">
    <visual>
      <geometry>
        <mesh filename="package://fellahbot_description/meshes/Fellahbot_DAE/Parts/Caster_Part-Body.dae"/>
      </geometry>
      <material name="black"/>
    </visual>
    <collision>
      <geometry>
        <mesh filename="package://fellahbot_description/meshes/Fellahbot_DAE/Parts/Caster_Part-Body.dae"/>
      </geometry>
    </collision>
    <xacro:default_inertial mass="6"/>
  </link>


  <link name="castor_2">
    <visual>
      <geometry>
        <mesh filename="package://fellahbot_description/meshes/Fellahbot_DAE/Parts/Caster_Part-Body.dae"/>
      </geometry>
      <material name="black"/>
    </visual>
    <collision>
      <geometry>
        <mesh filename="package://fellahbot_description/meshes/Fellahbot_DAE/Parts/Caster_Part-Body.dae"/>
      </geometry>
    </collision>
    <xacro:default_inertial mass="6"/>
  </link>

  <joint name="base_to_castor1" type="revolute">
    <parent link="chassis"/>
    <child link="castor_1"/>
    <axis xyz="0 0 1"/>
    <limit lower="-${math_pi_over_6}" upper="${math_pi_over_6}" velocity="50.0" effort="1000.0"/>
    <origin xyz="0.319 0.175 0.0"/>
  </joint>


  <joint name="base_to_castor2" type="revolute">
    <parent link="chassis"/>
    <child link="castor_2"/>
    <axis xyz="0 0 1"/>
    <limit lower="-${math_pi_over_6}" upper="${math_pi_over_6}" velocity="50.0" effort="1000.0"/>
    <origin xyz="0.319 -0.175 0.0"/>
  </joint>



  <link name="wheel_4">
    <visual>
      <geometry>
        <mesh filename="package://fellahbot_description/meshes/Fellahbot_DAE/Parts/Geared_Hub_Motor-Fusion001.dae"/>
      </geometry>
      <material name="black"/>
    </visual>
    <collision>
      <geometry>
        <mesh filename="package://fellahbot_description/meshes/Fellahbot_DAE/Parts/Geared_Hub_Motor-Fusion001.dae"/>
      </geometry>
    </collision>
    <xacro:default_inertial mass="6"/>
  </link>


  <link name="wheel_3">
    <visual>
      <geometry>
        <mesh filename="package://fellahbot_description/meshes/Fellahbot_DAE/Parts/Geared_Hub_Motor-Fusion001.dae"/>
      </geometry>
      <material name="black"/>
    </visual>
    <collision>
      <geometry>
        <mesh filename="package://fellahbot_description/meshes/Fellahbot_DAE/Parts/Geared_Hub_Motor-Fusion001.dae"/>
      </geometry>
    </collision>
    <xacro:default_inertial mass="6"/>
  </link>


  <link name="wheel_2">
    <visual>
      <geometry>
        <mesh filename="package://fellahbot_description/meshes/Fellahbot_DAE/Parts/Geared_Hub_Motor-Fusion001.dae"/>
      </geometry>
      <material name="black"/>
    </visual>
    <collision>
      <geometry>
        <mesh filename="package://fellahbot_description/meshes/Fellahbot_DAE/Parts/Geared_Hub_Motor-Fusion001.dae"/>
      </geometry>
    </collision>
    <xacro:default_inertial mass="6"/>
  </link>


  <link name="wheel_1">
    <visual>
      <geometry>
        <mesh filename="package://fellahbot_description/meshes/Fellahbot_DAE/Parts/Geared_Hub_Motor-Fusion001.dae"/>
      </geometry>
      <material name="black"/>
    </visual>
    <collision>
      <geometry>
        <mesh filename="package://fellahbot_description/meshes/Fellahbot_DAE/Parts/Geared_Hub_Motor-Fusion001.dae"/>
      </geometry>
    </collision>
    <xacro:default_inertial mass="6"/>
  </link>


  <joint name="base_to_wheel1" type="continuous">
    <parent link="chassis"/>
    <child link="wheel_1"/>
    <axis xyz="0 1 0"/>
    <origin xyz="-0.335 0.17523 -0.192"/>

  </joint>


  <joint name="base_to_wheel2" type="continuous">
    <parent link="chassis"/>
    <child link="wheel_2"/>
    <axis xyz="0 1 0"/>
    <origin xyz="-0.335 -0.17523 -0.192"/>

  </joint>


  <joint name="castor_to_wheel3" type="continuous">
    <parent link="castor_1"/>
    <child link="wheel_3"/>
    <axis xyz="0 1 0"/>
    <origin xyz="0.0 0.0 -0.192"/>

  </joint>


  <joint name="caster_to_wheel4" type="continuous">
    <parent link="castor_2"/>
    <child link="wheel_4"/>
    <axis xyz="0 1 0"/>
    <origin xyz="0.0 0.0 -0.192"/>

  </joint>



</robot>